ERROR 2018-10-24 11:33:42,487 exception 80 Invalid HTTP_HOST header: '127.0.0.1:8000'. You may need to add '127.0.0.1' to ALLOWED_HOSTS.
WARNING 2018-10-24 11:33:42,580 basehttp 124 "GET /sms_code/17607162138/ HTTP/1.1" 400 67797
ERROR 2018-10-24 11:46:40,582 exception 80 Invalid HTTP_HOST header: '127.0.0.1:8000'. You may need to add '127.0.0.1' to ALLOWED_HOSTS.
WARNING 2018-10-24 11:46:40,707 basehttp 124 "GET /sms_code/17607162138/ HTTP/1.1" 400 67841
ERROR 2018-10-24 11:46:41,290 exception 80 Invalid HTTP_HOST header: '127.0.0.1:8000'. You may need to add '127.0.0.1' to ALLOWED_HOSTS.
WARNING 2018-10-24 11:46:41,366 basehttp 124 "GET /favicon.ico HTTP/1.1" 400 67709
WARNING 2018-10-24 14:19:30,554 basehttp 124 "GET /sms_code/17607162138/ HTTP/1.1" 400 5196
INFO 2018-10-24 14:19:30,602 basehttp 124 "GET /static/rest_framework/css/bootstrap.min.css HTTP/1.1" 200 121200
INFO 2018-10-24 14:19:30,630 basehttp 124 "GET /static/rest_framework/css/bootstrap-tweaks.css HTTP/1.1" 200 3385
INFO 2018-10-24 14:19:30,643 basehttp 124 "GET /static/rest_framework/css/prettify.css HTTP/1.1" 200 817
INFO 2018-10-24 14:19:30,650 basehttp 124 "GET /static/rest_framework/css/default.css HTTP/1.1" 200 1131
INFO 2018-10-24 14:19:30,659 basehttp 124 "GET /static/rest_framework/js/jquery-3.3.1.min.js HTTP/1.1" 200 86927
INFO 2018-10-24 14:19:30,660 basehttp 124 "GET /static/rest_framework/js/csrf.js HTTP/1.1" 200 1735
INFO 2018-10-24 14:19:30,667 basehttp 124 "GET /static/rest_framework/js/ajax-form.js HTTP/1.1" 200 3597
INFO 2018-10-24 14:19:30,673 basehttp 124 "GET /static/rest_framework/js/bootstrap.min.js HTTP/1.1" 200 37045
INFO 2018-10-24 14:19:30,678 basehttp 124 "GET /static/rest_framework/js/default.js HTTP/1.1" 200 1268
INFO 2018-10-24 14:19:30,679 basehttp 124 "GET /static/rest_framework/js/prettify-min.js HTTP/1.1" 200 13632
INFO 2018-10-24 14:19:30,795 basehttp 124 "GET /static/rest_framework/img/grid.png HTTP/1.1" 200 1458
WARNING 2018-10-24 14:19:31,357 base 152 Not Found: /favicon.ico
WARNING 2018-10-24 14:19:31,359 basehttp 124 "GET /favicon.ico HTTP/1.1" 404 2159
WARNING 2018-10-24 14:20:09,229 base 152 Not Found: /mobiles/17607162138/count/
WARNING 2018-10-24 14:20:09,238 basehttp 124 "GET /mobiles/17607162138/count/ HTTP/1.1" 404 2204
WARNING 2018-10-24 14:20:09,284 basehttp 124 "GET /sms_code/17607162138/ HTTP/1.1" 400 40
WARNING 2018-10-24 14:20:09,285 base 152 Not Found: /mobiles/17607162138/count/
WARNING 2018-10-24 14:20:09,286 basehttp 124 "GET /mobiles/17607162138/count/ HTTP/1.1" 404 2204
WARNING 2018-10-24 14:20:27,165 base 152 Not Found: /mobiles/17607162138/count/
WARNING 2018-10-24 14:20:27,166 basehttp 124 "GET /mobiles/17607162138/count/ HTTP/1.1" 404 2204
ERROR 2018-10-24 14:20:27,174 exceptions 25 [<verifications.views.SMSCodeView object at 0x7fd29cdc9828>] Command # 1 (SETEX sms_code_17607162138 300 742390) of pipeline caused error: MISCONF Redis is configured to save RDB snapshots, but it is currently not able to persist on disk. Commands that may modify the data set are disabled, because this instance is configured to report errors during writes if RDB snapshotting fails (stop-writes-on-bgsave-error option). Please check the Redis logs for details about the RDB error.
ERROR 2018-10-24 14:20:27,175 basehttp 124 "GET /sms_code/17607162138/ HTTP/1.1" 507 35
WARNING 2018-10-24 14:25:57,504 base 152 Not Found: /mobiles/17607162138/count/
WARNING 2018-10-24 14:25:57,510 basehttp 124 "GET /mobiles/17607162138/count/ HTTP/1.1" 404 2204
INFO 2018-10-24 14:25:58,471 basehttp 124 "GET /sms_code/17607162138/ HTTP/1.1" 200 16
WARNING 2018-10-24 14:27:02,809 base 152 Not Found: /mobiles/17607162138/count/
WARNING 2018-10-24 14:27:02,813 basehttp 124 "GET /mobiles/17607162138/count/ HTTP/1.1" 404 2204
INFO 2018-10-24 14:27:03,662 basehttp 124 "GET /sms_code/17607162138/ HTTP/1.1" 200 16
WARNING 2018-10-24 14:28:05,339 base 152 Not Found: /mobiles/17607162138/count/
WARNING 2018-10-24 14:28:05,342 basehttp 124 "GET /mobiles/17607162138/count/ HTTP/1.1" 404 2204
INFO 2018-10-24 14:28:06,523 basehttp 124 "GET /sms_code/17607162138/ HTTP/1.1" 200 16
WARNING 2018-10-24 19:50:16,699 base 152 Not Found: /mobiles/17607162138/count/
WARNING 2018-10-24 19:50:16,705 basehttp 124 "GET /mobiles/17607162138/count/ HTTP/1.1" 404 2204
WARNING 2018-10-24 19:50:25,445 base 152 Not Found: /mobiles/17607162138/count/
WARNING 2018-10-24 19:50:25,446 basehttp 124 "GET /mobiles/17607162138/count/ HTTP/1.1" 404 2204
INFO 2018-10-24 19:50:26,490 basehttp 124 "GET /sms_code/17607162138/ HTTP/1.1" 200 16
WARNING 2018-10-24 19:52:39,547 base 152 Not Found: /mobiles/17607162138/count/
WARNING 2018-10-24 19:52:39,552 basehttp 124 "GET /mobiles/17607162138/count/ HTTP/1.1" 404 2204
INFO 2018-10-24 19:52:39,646 basehttp 124 "GET /sms_code/17607162138/ HTTP/1.1" 200 16
WARNING 2018-10-24 19:54:30,956 base 152 Not Found: /mobiles/17607162138/count/
WARNING 2018-10-24 19:54:30,963 basehttp 124 "GET /mobiles/17607162138/count/ HTTP/1.1" 404 2204
WARNING 2018-10-24 19:54:32,038 base 152 Not Found: /mobiles/17607162138/count/
WARNING 2018-10-24 19:54:32,039 basehttp 124 "GET /mobiles/17607162138/count/ HTTP/1.1" 404 2204
INFO 2018-10-24 19:54:32,065 basehttp 124 "GET /sms_code/17607162138/ HTTP/1.1" 200 16
ERROR 2018-10-24 20:16:31,491 exception 80 Invalid HTTP_HOST header: '127.0.0.1:8000'. You may need to add '127.0.0.1' to ALLOWED_HOSTS.
WARNING 2018-10-24 20:16:31,792 basehttp 124 "GET / HTTP/1.1" 400 67660
ERROR 2018-10-24 20:16:32,304 exception 80 Invalid HTTP_HOST header: '127.0.0.1:8000'. You may need to add '127.0.0.1' to ALLOWED_HOSTS.
WARNING 2018-10-24 20:16:32,388 basehttp 124 "GET /favicon.ico HTTP/1.1" 400 67738
INFO 2018-10-24 20:17:50,976 basehttp 124 "GET /usernames/12246y/count/ HTTP/1.1" 200 31
WARNING 2018-10-24 20:27:34,022 base 152 Not Found: /mobiles/17607162138/count/
WARNING 2018-10-24 20:27:34,023 basehttp 124 "GET /mobiles/17607162138/count/ HTTP/1.1" 404 2590
WARNING 2018-10-24 20:27:49,743 base 152 Not Found: /mobiles/18676663018/count/
WARNING 2018-10-24 20:27:49,751 basehttp 124 "GET /mobiles/18676663018/count/ HTTP/1.1" 404 2590
WARNING 2018-10-24 20:27:53,858 base 152 Not Found: /mobiles/18676663018/count/
WARNING 2018-10-24 20:27:53,861 basehttp 124 "GET /mobiles/18676663018/count/ HTTP/1.1" 404 2590
WARNING 2018-10-24 20:27:58,317 base 152 Not Found: /mobiles/18676663018/count/
WARNING 2018-10-24 20:27:58,325 basehttp 124 "GET /mobiles/18676663018/count/ HTTP/1.1" 404 2590
WARNING 2018-10-24 20:28:05,461 base 152 Not Found: /mobiles/18676663018/count/
WARNING 2018-10-24 20:28:05,463 basehttp 124 "GET /mobiles/18676663018/count/ HTTP/1.1" 404 2590
WARNING 2018-10-24 20:28:15,803 base 152 Not Found: /mobiles/17607162138/count/
WARNING 2018-10-24 20:28:15,814 basehttp 124 "GET /mobiles/17607162138/count/ HTTP/1.1" 404 2590
INFO 2018-10-24 20:30:42,813 basehttp 124 "GET /mobiles/17607162138/count/ HTTP/1.1" 200 41
INFO 2018-10-24 21:34:00,228 basehttp 124 "GET /mobiles/17607162138/count/ HTTP/1.1" 200 41
INFO 2018-10-24 21:34:00,440 basehttp 124 "GET /sms_code/17607162138/ HTTP/1.1" 200 16
INFO 2018-10-24 21:34:28,107 basehttp 124 "GET /usernames/12246y/count/ HTTP/1.1" 200 31
INFO 2018-10-24 21:34:28,123 basehttp 124 "OPTIONS /users/ HTTP/1.1" 200 0
INFO 2018-10-24 21:34:28,173 basehttp 124 "GET /mobiles/17607162138/count/ HTTP/1.1" 200 41
WARNING 2018-10-24 21:34:28,185 basehttp 124 "POST /users/ HTTP/1.1" 400 124
INFO 2018-10-24 21:35:47,067 basehttp 124 "GET /mobiles/17607162138/count/ HTTP/1.1" 200 41
INFO 2018-10-24 21:35:49,548 basehttp 124 "GET /mobiles/17607162138/count/ HTTP/1.1" 200 41
INFO 2018-10-24 21:35:49,764 basehttp 124 "GET /sms_code/17607162138/ HTTP/1.1" 200 16
INFO 2018-10-24 21:36:07,123 basehttp 124 "GET /usernames/12246y/count/ HTTP/1.1" 200 31
WARNING 2018-10-24 21:36:07,136 basehttp 124 "POST /users/ HTTP/1.1" 400 124
INFO 2018-10-24 21:36:07,159 basehttp 124 "GET /mobiles/17607162138/count/ HTTP/1.1" 200 41
INFO 2018-10-24 21:38:35,731 basehttp 124 "GET /mobiles/17607162138/count/ HTTP/1.1" 200 41
INFO 2018-10-24 21:38:38,256 basehttp 124 "GET /mobiles/17607162138/count/ HTTP/1.1" 200 41
INFO 2018-10-24 21:38:38,336 basehttp 124 "GET /sms_code/17607162138/ HTTP/1.1" 200 16
INFO 2018-10-24 21:38:54,357 basehttp 124 "GET /usernames/12246y/count/ HTTP/1.1" 200 31
WARNING 2018-10-24 21:38:54,365 basehttp 124 "POST /users/ HTTP/1.1" 400 90
INFO 2018-10-24 21:38:54,382 basehttp 124 "GET /mobiles/17607162138/count/ HTTP/1.1" 200 41
INFO 2018-10-24 21:40:25,379 basehttp 124 "GET /mobiles/17607162138/count/ HTTP/1.1" 200 41
INFO 2018-10-24 21:40:25,424 basehttp 124 "GET /sms_code/17607162138/ HTTP/1.1" 200 16
INFO 2018-10-24 21:40:35,169 basehttp 124 "GET /mobiles/17607162138/count/ HTTP/1.1" 200 41
INFO 2018-10-24 21:40:35,175 basehttp 124 "GET /usernames/12246y/count/ HTTP/1.1" 200 31
INFO 2018-10-24 21:40:35,479 basehttp 124 "POST /users/ HTTP/1.1" 201 45
INFO 2018-10-25 15:34:05,665 basehttp 124 "GET /usernames/12246y/count/ HTTP/1.1" 200 31
INFO 2018-10-25 15:34:26,079 basehttp 124 "GET /mobiles/17607162138/count/ HTTP/1.1" 200 41
INFO 2018-10-25 15:34:30,281 basehttp 124 "GET /mobiles/17607162138/count/ HTTP/1.1" 200 41
INFO 2018-10-25 15:34:30,546 basehttp 124 "GET /sms_code/17607162138/ HTTP/1.1" 200 16
INFO 2018-10-25 15:35:05,822 basehttp 124 "GET /mobiles/17607162138/count/ HTTP/1.1" 200 41
INFO 2018-10-25 15:35:12,222 basehttp 124 "GET /mobiles/17607162138/count/ HTTP/1.1" 200 41
INFO 2018-10-25 15:35:38,249 basehttp 124 "GET /mobiles/17607162138/count/ HTTP/1.1" 200 41
INFO 2018-10-25 15:35:39,347 basehttp 124 "GET /mobiles/17607162138/count/ HTTP/1.1" 200 41
INFO 2018-10-25 15:36:04,112 basehttp 124 "GET /mobiles/17607162138/count/ HTTP/1.1" 200 41
INFO 2018-10-26 16:28:57,252 basehttp 124 "GET /usernames/12246y/count/ HTTP/1.1" 200 31
INFO 2018-10-26 16:33:21,948 basehttp 124 "GET /mobiles/17607162138/count/ HTTP/1.1" 200 41
INFO 2018-10-26 16:33:23,733 basehttp 124 "GET /mobiles/17607162138/count/ HTTP/1.1" 200 41
INFO 2018-10-26 16:33:35,792 basehttp 124 "GET /usernames/12246y/count/ HTTP/1.1" 200 31
INFO 2018-10-26 16:33:35,811 basehttp 124 "OPTIONS /users/ HTTP/1.1" 200 0
INFO 2018-10-26 16:33:35,816 basehttp 124 "GET /mobiles/17607162138/count/ HTTP/1.1" 200 41
ERROR 2018-10-26 16:33:36,033 exceptions 25 [<users.views.UserCreateView object at 0x7f49e15c6e10>] (1062, "Duplicate entry '' for key 'username'")
ERROR 2018-10-26 16:33:36,034 basehttp 124 "POST /users/ HTTP/1.1" 507 35
INFO 2018-10-26 16:33:39,749 basehttp 124 "GET /mobiles/17607162138/count/ HTTP/1.1" 200 41
INFO 2018-10-26 16:33:39,750 basehttp 124 "GET /usernames/12246y/count/ HTTP/1.1" 200 31
ERROR 2018-10-26 16:33:39,793 exceptions 25 [<users.views.UserCreateView object at 0x7f49e0582748>] (1062, "Duplicate entry '' for key 'username'")
ERROR 2018-10-26 16:33:39,794 basehttp 124 "POST /users/ HTTP/1.1" 507 35
INFO 2018-10-26 16:34:23,775 basehttp 124 "GET /mobiles/17607162138/count/ HTTP/1.1" 200 41
ERROR 2018-10-26 16:34:58,729 exceptions 25 [<verifications.views.SMSCodeView object at 0x7f49e052e0b8>] Command # 1 (SETEX sms_code_17607162138 300 704918) of pipeline caused error: MISCONF Redis is configured to save RDB snapshots, but it is currently not able to persist on disk. Commands that may modify the data set are disabled, because this instance is configured to report errors during writes if RDB snapshotting fails (stop-writes-on-bgsave-error option). Please check the Redis logs for details about the RDB error.
INFO 2018-10-26 16:34:58,734 basehttp 124 "GET /mobiles/17607162138/count/ HTTP/1.1" 200 41
ERROR 2018-10-26 16:34:58,740 basehttp 124 "GET /sms_code/17607162138/ HTTP/1.1" 507 35
INFO 2018-10-26 16:34:58,775 basehttp 124 "GET /mobiles/17607162138/count/ HTTP/1.1" 200 41
ERROR 2018-10-26 16:35:38,408 exceptions 25 [<verifications.views.SMSCodeView object at 0x7f49e053b710>] Command # 1 (SETEX sms_code_17607162138 300 485307) of pipeline caused error: MISCONF Redis is configured to save RDB snapshots, but it is currently not able to persist on disk. Commands that may modify the data set are disabled, because this instance is configured to report errors during writes if RDB snapshotting fails (stop-writes-on-bgsave-error option). Please check the Redis logs for details about the RDB error.
ERROR 2018-10-26 16:35:38,423 basehttp 124 "GET /sms_code/17607162138/ HTTP/1.1" 507 35
INFO 2018-10-26 16:35:38,429 basehttp 124 "GET /mobiles/17607162138/count/ HTTP/1.1" 200 41
INFO 2018-10-26 16:38:28,701 basehttp 124 "GET /sms_code/17607162138/ HTTP/1.1" 200 16
INFO 2018-10-26 16:38:29,318 basehttp 124 "GET /usernames/12246y/count/ HTTP/1.1" 200 31
INFO 2018-10-26 16:38:43,041 basehttp 124 "GET /sms_code/17607162138/ HTTP/1.1" 200 16
INFO 2018-10-26 16:38:43,055 basehttp 124 "GET /mobiles/17607162138/count/ HTTP/1.1" 200 41
INFO 2018-10-26 16:39:08,495 basehttp 124 "GET /usernames/12246y/count/ HTTP/1.1" 200 31
INFO 2018-10-26 16:39:08,504 basehttp 124 "GET /mobiles/17607162138/count/ HTTP/1.1" 200 41
ERROR 2018-10-26 16:39:08,561 exceptions 25 [<users.views.UserCreateView object at 0x7f49e0582198>] (1062, "Duplicate entry '' for key 'username'")
ERROR 2018-10-26 16:39:08,565 basehttp 124 "POST /users/ HTTP/1.1" 507 35
INFO 2018-10-26 16:39:43,943 basehttp 124 "GET /usernames/12246y/count/ HTTP/1.1" 200 31
INFO 2018-10-26 16:39:43,949 basehttp 124 "GET /mobiles/17607162138/count/ HTTP/1.1" 200 41
ERROR 2018-10-26 16:39:44,123 exceptions 25 [<users.views.UserCreateView object at 0x7f49e04df1d0>] (1062, "Duplicate entry '' for key 'username'")
ERROR 2018-10-26 16:39:44,125 basehttp 124 "POST /users/ HTTP/1.1" 507 35
INFO 2018-10-26 16:40:58,571 basehttp 124 "GET /mobiles/17607162138/count/ HTTP/1.1" 200 41
INFO 2018-10-26 16:40:58,609 basehttp 124 "GET /sms_code/17607162138/ HTTP/1.1" 200 16
INFO 2018-10-26 16:41:13,342 basehttp 124 "GET /mobiles/17607162138/count/ HTTP/1.1" 200 41
INFO 2018-10-26 16:41:13,345 basehttp 124 "GET /usernames/12246y/count/ HTTP/1.1" 200 31
ERROR 2018-10-26 16:41:13,488 exceptions 25 [<users.views.UserCreateView object at 0x7f3c1414a860>] (1062, "Duplicate entry '17607162138' for key 'mobile'")
ERROR 2018-10-26 16:41:13,490 basehttp 124 "POST /users/ HTTP/1.1" 507 35
INFO 2018-10-26 17:19:25,143 basehttp 124 "GET /mobiles/17607162138/count/ HTTP/1.1" 200 41
INFO 2018-10-26 17:19:25,207 basehttp 124 "GET /sms_code/17607162138/ HTTP/1.1" 200 16
INFO 2018-10-26 17:19:44,151 basehttp 124 "GET /mobiles/17607162138/count/ HTTP/1.1" 200 41
INFO 2018-10-26 17:19:44,161 basehttp 124 "OPTIONS /users/ HTTP/1.1" 200 0
INFO 2018-10-26 17:19:44,177 basehttp 124 "GET /usernames/12246y/count/ HTTP/1.1" 200 31
ERROR 2018-10-26 17:19:44,324 exceptions 25 [<users.views.UserCreateView object at 0x7f7b25e70c50>] (1062, "Duplicate entry '17607162138' for key 'mobile'")
ERROR 2018-10-26 17:19:44,326 basehttp 124 "POST /users/ HTTP/1.1" 507 35
INFO 2018-10-28 09:45:19,666 basehttp 124 "GET /usernames/12246y/count/ HTTP/1.1" 200 31
INFO 2018-10-28 09:45:33,321 basehttp 124 "GET /usernames/12246y/count/ HTTP/1.1" 200 31
INFO 2018-10-28 09:47:03,391 basehttp 124 "GET /mobiles/17607162138/count/ HTTP/1.1" 200 41
INFO 2018-10-28 09:47:03,433 basehttp 124 "GET /mobiles/17607162138/count/ HTTP/1.1" 200 41
INFO 2018-10-28 09:48:14,098 basehttp 124 "GET /mobiles/17607162137/count/ HTTP/1.1" 200 41
INFO 2018-10-28 09:50:19,686 basehttp 124 "GET /usernames/12246y/count/ HTTP/1.1" 200 31
INFO 2018-10-28 09:50:47,892 basehttp 124 "GET /mobiles/17607162138/count/ HTTP/1.1" 200 41
INFO 2018-10-28 09:50:47,930 basehttp 124 "GET /mobiles/17607162138/count/ HTTP/1.1" 200 41
ERROR 2018-10-28 09:50:47,939 exceptions 25 [<verifications.views.SMSCodeView object at 0x7f24d520d2b0>] Command # 1 (SETEX sms_code_17607162138 300 123456) of pipeline caused error: MISCONF Redis is configured to save RDB snapshots, but it is currently not able to persist on disk. Commands that may modify the data set are disabled, because this instance is configured to report errors during writes if RDB snapshotting fails (stop-writes-on-bgsave-error option). Please check the Redis logs for details about the RDB error.
ERROR 2018-10-28 09:50:47,940 basehttp 124 "GET /sms_code/17607162138/ HTTP/1.1" 507 35
INFO 2018-10-28 09:53:54,032 basehttp 124 "GET /mobiles/17607162138/count/ HTTP/1.1" 200 41
INFO 2018-10-28 09:53:54,109 basehttp 124 "GET /sms_code/17607162138/ HTTP/1.1" 200 16
INFO 2018-10-28 09:54:07,635 basehttp 124 "OPTIONS /users/ HTTP/1.1" 200 0
INFO 2018-10-28 09:54:07,638 basehttp 124 "GET /usernames/12246y/count/ HTTP/1.1" 200 31
INFO 2018-10-28 09:54:07,652 basehttp 124 "GET /mobiles/17607162138/count/ HTTP/1.1" 200 41
INFO 2018-10-28 09:54:07,785 basehttp 124 "POST /users/ HTTP/1.1" 201 225
INFO 2018-10-28 09:57:48,990 basehttp 124 "OPTIONS /authorizations/ HTTP/1.1" 200 0
WARNING 2018-10-28 09:57:49,082 basehttp 124 "POST /authorizations/ HTTP/1.1" 400 67
INFO 2018-10-28 09:58:08,957 basehttp 124 "POST /authorizations/ HTTP/1.1" 200 207
WARNING 2018-10-28 09:59:08,529 basehttp 124 "POST /authorizations/ HTTP/1.1" 400 67
INFO 2018-10-28 10:16:50,087 basehttp 124 "OPTIONS /authorizations/ HTTP/1.1" 200 0
WARNING 2018-10-28 10:16:50,219 basehttp 124 "POST /authorizations/ HTTP/1.1" 400 67
INFO 2018-10-28 10:20:56,816 basehttp 124 "POST /authorizations/ HTTP/1.1" 200 207
INFO 2018-10-28 11:24:26,009 basehttp 124 "GET /oauth/qq/authorization/?next=/ HTTP/1.1" 200 195
INFO 2018-10-28 13:55:20,121 basehttp 124 "GET /oauth/qq/authorization/?next=/ HTTP/1.1" 200 195
ERROR 2018-10-28 13:59:55,109 qq_sdk 59 code=None msg=None
ERROR 2018-10-28 13:59:55,111 exception 135 Internal Server Error: /oauth/qq/user/
Traceback (most recent call last):
  File "/home/python/.virtualenvs/django_py3_1.11/lib/python3.6/site-packages/django/core/handlers/exception.py", line 41, in inner
    response = get_response(request)
  File "/home/python/.virtualenvs/django_py3_1.11/lib/python3.6/site-packages/django/core/handlers/base.py", line 187, in _get_response
    response = self.process_exception_by_middleware(e, request)
  File "/home/python/.virtualenvs/django_py3_1.11/lib/python3.6/site-packages/django/core/handlers/base.py", line 185, in _get_response
    response = wrapped_callback(request, *callback_args, **callback_kwargs)
  File "/home/python/.virtualenvs/django_py3_1.11/lib/python3.6/site-packages/django/views/decorators/csrf.py", line 58, in wrapped_view
    return view_func(*args, **kwargs)
  File "/home/python/.virtualenvs/django_py3_1.11/lib/python3.6/site-packages/django/views/generic/base.py", line 68, in view
    return self.dispatch(request, *args, **kwargs)
  File "/home/python/.virtualenvs/django_py3_1.11/lib/python3.6/site-packages/rest_framework/views.py", line 495, in dispatch
    response = self.handle_exception(exc)
  File "/home/python/.virtualenvs/django_py3_1.11/lib/python3.6/site-packages/rest_framework/views.py", line 455, in handle_exception
    self.raise_uncaught_exception(exc)
  File "/home/python/.virtualenvs/django_py3_1.11/lib/python3.6/site-packages/rest_framework/views.py", line 492, in dispatch
    response = handler(request, *args, **kwargs)
  File "/home/python/Desktop/meiduo/meiduo111/meiduo111/apps/oauth/views.py", line 33, in get
    token = oauthqq.get_access_token(code)
  File "/home/python/Desktop/meiduo/meiduo111/meiduo111/apps/oauth/qq_sdk.py", line 60, in get_access_token
    raise Exception('获取access token失败')
Exception: 获取access token失败
ERROR 2018-10-28 13:59:55,369 basehttp 124 "GET /oauth/qq/user/?code=53807325E0814592F05DAB0264FF0055 HTTP/1.1" 500 17592
ERROR 2018-10-28 14:33:57,896 qq_sdk 59 code=None msg=None
ERROR 2018-10-28 14:33:57,897 exception 135 Internal Server Error: /oauth/qq/user/
Traceback (most recent call last):
  File "/home/python/.virtualenvs/django_py3_1.11/lib/python3.6/site-packages/django/core/handlers/exception.py", line 41, in inner
    response = get_response(request)
  File "/home/python/.virtualenvs/django_py3_1.11/lib/python3.6/site-packages/django/core/handlers/base.py", line 187, in _get_response
    response = self.process_exception_by_middleware(e, request)
  File "/home/python/.virtualenvs/django_py3_1.11/lib/python3.6/site-packages/django/core/handlers/base.py", line 185, in _get_response
    response = wrapped_callback(request, *callback_args, **callback_kwargs)
  File "/home/python/.virtualenvs/django_py3_1.11/lib/python3.6/site-packages/django/views/decorators/csrf.py", line 58, in wrapped_view
    return view_func(*args, **kwargs)
  File "/home/python/.virtualenvs/django_py3_1.11/lib/python3.6/site-packages/django/views/generic/base.py", line 68, in view
    return self.dispatch(request, *args, **kwargs)
  File "/home/python/.virtualenvs/django_py3_1.11/lib/python3.6/site-packages/rest_framework/views.py", line 495, in dispatch
    response = self.handle_exception(exc)
  File "/home/python/.virtualenvs/django_py3_1.11/lib/python3.6/site-packages/rest_framework/views.py", line 455, in handle_exception
    self.raise_uncaught_exception(exc)
  File "/home/python/.virtualenvs/django_py3_1.11/lib/python3.6/site-packages/rest_framework/views.py", line 492, in dispatch
    response = handler(request, *args, **kwargs)
  File "/home/python/Desktop/meiduo/meiduo111/meiduo111/apps/oauth/views.py", line 34, in get
    token = oauthqq.get_access_token(code)
  File "/home/python/Desktop/meiduo/meiduo111/meiduo111/apps/oauth/qq_sdk.py", line 60, in get_access_token
    raise Exception('获取access token失败')
Exception: 获取access token失败
ERROR 2018-10-28 14:33:57,966 basehttp 124 "GET /oauth/qq/user/?code=53807325E0814592F05DAB0264FF0055 HTTP/1.1" 500 17592
ERROR 2018-10-28 14:34:09,332 qq_sdk 59 code=None msg=None
ERROR 2018-10-28 14:34:09,332 exception 135 Internal Server Error: /oauth/qq/user/
Traceback (most recent call last):
  File "/home/python/.virtualenvs/django_py3_1.11/lib/python3.6/site-packages/django/core/handlers/exception.py", line 41, in inner
    response = get_response(request)
  File "/home/python/.virtualenvs/django_py3_1.11/lib/python3.6/site-packages/django/core/handlers/base.py", line 187, in _get_response
    response = self.process_exception_by_middleware(e, request)
  File "/home/python/.virtualenvs/django_py3_1.11/lib/python3.6/site-packages/django/core/handlers/base.py", line 185, in _get_response
    response = wrapped_callback(request, *callback_args, **callback_kwargs)
  File "/home/python/.virtualenvs/django_py3_1.11/lib/python3.6/site-packages/django/views/decorators/csrf.py", line 58, in wrapped_view
    return view_func(*args, **kwargs)
  File "/home/python/.virtualenvs/django_py3_1.11/lib/python3.6/site-packages/django/views/generic/base.py", line 68, in view
    return self.dispatch(request, *args, **kwargs)
  File "/home/python/.virtualenvs/django_py3_1.11/lib/python3.6/site-packages/rest_framework/views.py", line 495, in dispatch
    response = self.handle_exception(exc)
  File "/home/python/.virtualenvs/django_py3_1.11/lib/python3.6/site-packages/rest_framework/views.py", line 455, in handle_exception
    self.raise_uncaught_exception(exc)
  File "/home/python/.virtualenvs/django_py3_1.11/lib/python3.6/site-packages/rest_framework/views.py", line 492, in dispatch
    response = handler(request, *args, **kwargs)
  File "/home/python/Desktop/meiduo/meiduo111/meiduo111/apps/oauth/views.py", line 34, in get
    token = oauthqq.get_access_token(code)
  File "/home/python/Desktop/meiduo/meiduo111/meiduo111/apps/oauth/qq_sdk.py", line 60, in get_access_token
    raise Exception('获取access token失败')
Exception: 获取access token失败
ERROR 2018-10-28 14:34:09,378 basehttp 124 "GET /oauth/qq/user/?code=53807325E0814592F05DAB0264FF0055 HTTP/1.1" 500 17592
INFO 2018-10-28 14:34:40,745 basehttp 124 "OPTIONS /authorizations/ HTTP/1.1" 200 0
INFO 2018-10-28 14:34:40,846 basehttp 124 "POST /authorizations/ HTTP/1.1" 200 207
INFO 2018-10-28 14:34:58,485 basehttp 124 "GET /oauth/qq/authorization/?next=/ HTTP/1.1" 200 195
INFO 2018-10-28 14:35:29,189 basehttp 124 "GET /oauth/qq/authorization/?next=/ HTTP/1.1" 200 195
INFO 2018-10-28 14:35:44,908 basehttp 124 "GET /oauth/qq/authorization/?next=/ HTTP/1.1" 200 195
INFO 2018-10-28 14:35:46,343 basehttp 124 "GET /oauth/qq/authorization/?next=/ HTTP/1.1" 200 195
INFO 2018-10-28 14:36:06,635 basehttp 124 "GET /oauth/qq/authorization/?next=/ HTTP/1.1" 200 195
ERROR 2018-10-28 14:57:38,665 qq_sdk 59 code=None msg=None
ERROR 2018-10-28 14:57:38,666 exception 135 Internal Server Error: /oauth/qq/user/
Traceback (most recent call last):
  File "/home/python/.virtualenvs/django_py3_1.11/lib/python3.6/site-packages/django/core/handlers/exception.py", line 41, in inner
    response = get_response(request)
  File "/home/python/.virtualenvs/django_py3_1.11/lib/python3.6/site-packages/django/core/handlers/base.py", line 187, in _get_response
    response = self.process_exception_by_middleware(e, request)
  File "/home/python/.virtualenvs/django_py3_1.11/lib/python3.6/site-packages/django/core/handlers/base.py", line 185, in _get_response
    response = wrapped_callback(request, *callback_args, **callback_kwargs)
  File "/home/python/.virtualenvs/django_py3_1.11/lib/python3.6/site-packages/django/views/decorators/csrf.py", line 58, in wrapped_view
    return view_func(*args, **kwargs)
  File "/home/python/.virtualenvs/django_py3_1.11/lib/python3.6/site-packages/django/views/generic/base.py", line 68, in view
    return self.dispatch(request, *args, **kwargs)
  File "/home/python/.virtualenvs/django_py3_1.11/lib/python3.6/site-packages/rest_framework/views.py", line 495, in dispatch
    response = self.handle_exception(exc)
  File "/home/python/.virtualenvs/django_py3_1.11/lib/python3.6/site-packages/rest_framework/views.py", line 455, in handle_exception
    self.raise_uncaught_exception(exc)
  File "/home/python/.virtualenvs/django_py3_1.11/lib/python3.6/site-packages/rest_framework/views.py", line 492, in dispatch
    response = handler(request, *args, **kwargs)
  File "/home/python/Desktop/meiduo/meiduo111/meiduo111/apps/oauth/views.py", line 34, in get
    token = oauthqq.get_access_token(code)
  File "/home/python/Desktop/meiduo/meiduo111/meiduo111/apps/oauth/qq_sdk.py", line 60, in get_access_token
    raise Exception('获取access token失败')
Exception: 获取access token失败
ERROR 2018-10-28 14:57:38,720 basehttp 124 "GET /oauth/qq/user/?code=853AE4C8CDEE006756E2CD5CFE80CB26 HTTP/1.1" 500 17592
INFO 2018-10-28 15:02:36,574 basehttp 124 "GET /oauth/qq/authorization/?next=/ HTTP/1.1" 200 195
INFO 2018-10-28 15:02:55,747 basehttp 124 "GET /oauth/qq/authorization/?next=/ HTTP/1.1" 200 195
INFO 2018-10-28 15:03:34,942 basehttp 124 "GET /oauth/qq/authorization/?next=/ HTTP/1.1" 200 195
ERROR 2018-10-28 15:03:36,553 exception 135 Internal Server Error: /oauth/qq/user/
Traceback (most recent call last):
  File "/usr/lib/python3.6/urllib/request.py", line 1318, in do_open
    encode_chunked=req.has_header('Transfer-encoding'))
  File "/usr/lib/python3.6/http/client.py", line 1239, in request
    self._send_request(method, url, body, headers, encode_chunked)
  File "/usr/lib/python3.6/http/client.py", line 1285, in _send_request
    self.endheaders(body, encode_chunked=encode_chunked)
  File "/usr/lib/python3.6/http/client.py", line 1234, in endheaders
    self._send_output(message_body, encode_chunked=encode_chunked)
  File "/usr/lib/python3.6/http/client.py", line 1026, in _send_output
    self.send(msg)
  File "/usr/lib/python3.6/http/client.py", line 964, in send
    self.connect()
  File "/usr/lib/python3.6/http/client.py", line 1392, in connect
    super().connect()
  File "/usr/lib/python3.6/http/client.py", line 936, in connect
    (self.host,self.port), self.timeout, self.source_address)
  File "/usr/lib/python3.6/socket.py", line 724, in create_connection
    raise err
  File "/usr/lib/python3.6/socket.py", line 713, in create_connection
    sock.connect(sa)
ConnectionRefusedError: [Errno 111] Connection refused

During handling of the above exception, another exception occurred:

Traceback (most recent call last):
  File "/home/python/.virtualenvs/django_py3_1.11/lib/python3.6/site-packages/django/core/handlers/exception.py", line 41, in inner
    response = get_response(request)
  File "/home/python/.virtualenvs/django_py3_1.11/lib/python3.6/site-packages/django/core/handlers/base.py", line 187, in _get_response
    response = self.process_exception_by_middleware(e, request)
  File "/home/python/.virtualenvs/django_py3_1.11/lib/python3.6/site-packages/django/core/handlers/base.py", line 185, in _get_response
    response = wrapped_callback(request, *callback_args, **callback_kwargs)
  File "/home/python/.virtualenvs/django_py3_1.11/lib/python3.6/site-packages/django/views/decorators/csrf.py", line 58, in wrapped_view
    return view_func(*args, **kwargs)
  File "/home/python/.virtualenvs/django_py3_1.11/lib/python3.6/site-packages/django/views/generic/base.py", line 68, in view
    return self.dispatch(request, *args, **kwargs)
  File "/home/python/.virtualenvs/django_py3_1.11/lib/python3.6/site-packages/rest_framework/views.py", line 495, in dispatch
    response = self.handle_exception(exc)
  File "/home/python/.virtualenvs/django_py3_1.11/lib/python3.6/site-packages/rest_framework/views.py", line 455, in handle_exception
    self.raise_uncaught_exception(exc)
  File "/home/python/.virtualenvs/django_py3_1.11/lib/python3.6/site-packages/rest_framework/views.py", line 492, in dispatch
    response = handler(request, *args, **kwargs)
  File "/home/python/Desktop/meiduo/meiduo111/meiduo111/apps/oauth/views.py", line 34, in get
    token = oauthqq.get_access_token(code)
  File "/home/python/Desktop/meiduo/meiduo111/meiduo111/apps/oauth/qq_sdk.py", line 54, in get_access_token
    response = urlopen(url)
  File "/usr/lib/python3.6/urllib/request.py", line 223, in urlopen
    return opener.open(url, data, timeout)
  File "/usr/lib/python3.6/urllib/request.py", line 526, in open
    response = self._open(req, data)
  File "/usr/lib/python3.6/urllib/request.py", line 544, in _open
    '_open', req)
  File "/usr/lib/python3.6/urllib/request.py", line 504, in _call_chain
    result = func(*args)
  File "/usr/lib/python3.6/urllib/request.py", line 1361, in https_open
    context=self._context, check_hostname=self._check_hostname)
  File "/usr/lib/python3.6/urllib/request.py", line 1320, in do_open
    raise URLError(err)
urllib.error.URLError: <urlopen error [Errno 111] Connection refused>
ERROR 2018-10-28 15:03:36,678 basehttp 124 "GET /oauth/qq/user/?code=853AE4C8CDEE006756E2CD5CFE80CB26 HTTP/1.1" 500 19504
ERROR 2018-10-28 15:08:21,779 qq_sdk 59 code=None msg=None
ERROR 2018-10-28 15:08:21,780 exception 135 Internal Server Error: /oauth/qq/user/
Traceback (most recent call last):
  File "/home/python/.virtualenvs/django_py3_1.11/lib/python3.6/site-packages/django/core/handlers/exception.py", line 41, in inner
    response = get_response(request)
  File "/home/python/.virtualenvs/django_py3_1.11/lib/python3.6/site-packages/django/core/handlers/base.py", line 187, in _get_response
    response = self.process_exception_by_middleware(e, request)
  File "/home/python/.virtualenvs/django_py3_1.11/lib/python3.6/site-packages/django/core/handlers/base.py", line 185, in _get_response
    response = wrapped_callback(request, *callback_args, **callback_kwargs)
  File "/home/python/.virtualenvs/django_py3_1.11/lib/python3.6/site-packages/django/views/decorators/csrf.py", line 58, in wrapped_view
    return view_func(*args, **kwargs)
  File "/home/python/.virtualenvs/django_py3_1.11/lib/python3.6/site-packages/django/views/generic/base.py", line 68, in view
    return self.dispatch(request, *args, **kwargs)
  File "/home/python/.virtualenvs/django_py3_1.11/lib/python3.6/site-packages/rest_framework/views.py", line 495, in dispatch
    response = self.handle_exception(exc)
  File "/home/python/.virtualenvs/django_py3_1.11/lib/python3.6/site-packages/rest_framework/views.py", line 455, in handle_exception
    self.raise_uncaught_exception(exc)
  File "/home/python/.virtualenvs/django_py3_1.11/lib/python3.6/site-packages/rest_framework/views.py", line 492, in dispatch
    response = handler(request, *args, **kwargs)
  File "/home/python/Desktop/meiduo/meiduo111/meiduo111/apps/oauth/views.py", line 34, in get
    token = oauthqq.get_access_token(code)
  File "/home/python/Desktop/meiduo/meiduo111/meiduo111/apps/oauth/qq_sdk.py", line 60, in get_access_token
    raise Exception('获取access token失败')
Exception: 获取access token失败
ERROR 2018-10-28 15:08:21,803 basehttp 124 "GET /oauth/qq/user/?code=2C9F6F12AE7025F408BBAD1979855B46 HTTP/1.1" 500 17592
INFO 2018-10-28 15:10:02,872 basehttp 124 "GET /oauth/qq/authorization/?next=/ HTTP/1.1" 200 195
ERROR 2018-10-28 15:10:19,314 exception 135 Internal Server Error: /oauth/qq/user/
Traceback (most recent call last):
  File "/home/python/Desktop/meiduo/meiduo111/meiduo111/apps/oauth/views.py", line 41, in get
    qquser=OAuthQQuser.objects.get(openid=openid)
  File "/home/python/.virtualenvs/django_py3_1.11/lib/python3.6/site-packages/django/db/models/manager.py", line 85, in manager_method
    return getattr(self.get_queryset(), name)(*args, **kwargs)
  File "/home/python/.virtualenvs/django_py3_1.11/lib/python3.6/site-packages/django/db/models/query.py", line 379, in get
    self.model._meta.object_name
oauth.models.DoesNotExist: OAuthQQuser matching query does not exist.

During handling of the above exception, another exception occurred:

Traceback (most recent call last):
  File "/home/python/.virtualenvs/django_py3_1.11/lib/python3.6/site-packages/django/core/handlers/exception.py", line 41, in inner
    response = get_response(request)
  File "/home/python/.virtualenvs/django_py3_1.11/lib/python3.6/site-packages/django/core/handlers/base.py", line 187, in _get_response
    response = self.process_exception_by_middleware(e, request)
  File "/home/python/.virtualenvs/django_py3_1.11/lib/python3.6/site-packages/django/core/handlers/base.py", line 185, in _get_response
    response = wrapped_callback(request, *callback_args, **callback_kwargs)
  File "/home/python/.virtualenvs/django_py3_1.11/lib/python3.6/site-packages/django/views/decorators/csrf.py", line 58, in wrapped_view
    return view_func(*args, **kwargs)
  File "/home/python/.virtualenvs/django_py3_1.11/lib/python3.6/site-packages/django/views/generic/base.py", line 68, in view
    return self.dispatch(request, *args, **kwargs)
  File "/home/python/.virtualenvs/django_py3_1.11/lib/python3.6/site-packages/rest_framework/views.py", line 495, in dispatch
    response = self.handle_exception(exc)
  File "/home/python/.virtualenvs/django_py3_1.11/lib/python3.6/site-packages/rest_framework/views.py", line 455, in handle_exception
    self.raise_uncaught_exception(exc)
  File "/home/python/.virtualenvs/django_py3_1.11/lib/python3.6/site-packages/rest_framework/views.py", line 492, in dispatch
    response = handler(request, *args, **kwargs)
  File "/home/python/Desktop/meiduo/meiduo111/meiduo111/apps/oauth/views.py", line 45, in get
    data = tjwt.dumps({'openid':openid},constants.BIND_TOKEN_EXPIRES)
NameError: name 'tjwt' is not defined
ERROR 2018-10-28 15:10:19,381 basehttp 124 "GET /oauth/qq/user/?code=A23EEB0AF1348F5D213965DB5D1A8D23 HTTP/1.1" 500 18118
INFO 2018-10-28 15:13:59,872 basehttp 124 "GET /oauth/qq/authorization/?next=/ HTTP/1.1" 200 195
INFO 2018-10-28 15:14:17,653 basehttp 124 "GET /oauth/qq/user/?code=2AA555F315444011015E660F992F6A30 HTTP/1.1" 200 233
INFO 2018-10-28 15:14:17,683 basehttp 124 "GET /oauth/qq/user/?code=1451E9D04496E4A269AB1737E27341FF HTTP/1.1" 200 233
INFO 2018-10-28 15:14:38,255 basehttp 124 "GET /sms_code/17607162138/ HTTP/1.1" 200 16
INFO 2018-10-28 15:14:48,473 basehttp 124 "OPTIONS /oauth/qq/user/ HTTP/1.1" 200 0
INFO 2018-10-28 15:14:48,517 basehttp 124 "POST /oauth/qq/user/ HTTP/1.1" 200 53
INFO 2018-10-28 15:15:56,983 basehttp 124 "GET /oauth/qq/authorization/?next=/ HTTP/1.1" 200 195
INFO 2018-10-28 15:17:01,366 basehttp 124 "GET /oauth/qq/user/?code=FA2F13929A1C5854AFF70B69EB99F81F HTTP/1.1" 200 233
INFO 2018-10-28 15:17:12,830 basehttp 124 "GET /sms_code/17607162138/ HTTP/1.1" 200 16
INFO 2018-10-28 15:17:18,346 basehttp 124 "OPTIONS /oauth/qq/user/ HTTP/1.1" 200 0
INFO 2018-10-28 15:17:18,407 basehttp 124 "POST /oauth/qq/user/ HTTP/1.1" 200 53
INFO 2018-10-28 15:19:06,108 basehttp 124 "GET /oauth/qq/authorization/?next=/ HTTP/1.1" 200 195
INFO 2018-10-28 15:19:25,061 basehttp 124 "GET /oauth/qq/user/?code=39D9AE3991351608E82B6D3D7A2136D7 HTTP/1.1" 200 233
INFO 2018-10-28 15:19:37,605 basehttp 124 "GET /sms_code/17607162138/ HTTP/1.1" 200 16
INFO 2018-10-28 15:19:44,623 basehttp 124 "OPTIONS /oauth/qq/user/ HTTP/1.1" 200 0
INFO 2018-10-28 15:19:44,768 basehttp 124 "POST /oauth/qq/user/ HTTP/1.1" 200 207
INFO 2018-10-28 15:19:57,219 basehttp 124 "OPTIONS /user/ HTTP/1.1" 200 0
WARNING 2018-10-28 15:19:57,392 base 152 Not Found: /user/
WARNING 2018-10-28 15:19:57,394 basehttp 124 "GET /user/ HTTP/1.1" 404 2943
INFO 2018-10-28 15:22:01,220 basehttp 124 "GET /user/ HTTP/1.1" 200 83
INFO 2018-10-28 15:22:01,350 basehttp 124 "OPTIONS /browse_histories/ HTTP/1.1" 200 0
WARNING 2018-10-28 15:22:01,922 base 152 Not Found: /browse_histories/
WARNING 2018-10-28 15:22:01,925 basehttp 124 "GET /browse_histories/ HTTP/1.1" 404 2978
INFO 2018-10-28 15:25:47,936 basehttp 124 code 400, message Bad request syntax ('\x16\x03\x01\x02\x00\x01\x00\x01ü\x03\x03µ\x93úX\x95\'¶q\x15X´®Ãä \x06¦Öj\x05\x0cýë?t\r£\x0eí$ot nÜß»¯P¤cODæ\x9fD\x0eº\x89·Æå\x17øy\x8bÙrL½\x01\x01ÞQ\x88\x00"ÊÊ\x13\x01\x13\x02\x13\x03À+À/À,À0Ì©Ì¨À\x13À\x14\x00\x9c\x00\x9d\x00/\x005\x00')
ERROR 2018-10-28 15:25:47,937 basehttp 107 You're accessing the development server over HTTPS, but it only supports HTTP.

INFO 2018-10-28 15:25:47,940 basehttp 124 code 400, message Bad request syntax ('\x16\x03\x01\x00Í\x01\x00\x00É\x03\x037M\x1f\x90Ê"\x19³\x17#=\x12FZ\x0cm\x92}ð³¯Å8Ä¾Í\x14\x08Ìö®\x86\x00\x00\x1cêêÀ+À/À,À0Ì©Ì¨À\x13À\x14\x00\x9c\x00\x9d\x00/\x005\x00')
ERROR 2018-10-28 15:25:47,940 basehttp 107 You're accessing the development server over HTTPS, but it only supports HTTP.

INFO 2018-10-28 15:26:10,608 basehttp 124 "GET /sms_code/17607162138/ HTTP/1.1" 200 16
